2025-08-03 16:17:55 +0000 - dagster - DEBUG - __ASSET_JOB - 895cb7f3-f5cd-4349-822b-c5fa51f2bde7 - 2031 - LOGS_CAPTURED - Started capturing logs in process (pid: 2031).
2025-08-03 16:17:55 +0000 - dagster - DEBUG - __ASSET_JOB - 895cb7f3-f5cd-4349-822b-c5fa51f2bde7 - 2031 - trigger_transform_api - STEP_START - Started execution of step "trigger_transform_api".
Failed to call transform API: [Errno -3] Temporary failure in name resolution
2025-08-03 16:17:55 +0000 - dagster - ERROR - __ASSET_JOB - 895cb7f3-f5cd-4349-822b-c5fa51f2bde7 - 2031 - trigger_transform_api - STEP_FAILURE - Execution of step "trigger_transform_api" failed.

dagster._core.errors.DagsterExecutionStepExecutionError: Error occurred while executing op "trigger_transform_api"::

httpx.ConnectError: [Errno -3] Temporary failure in name resolution

Stack Trace:
  File "/usr/local/lib/python3.10/site-packages/dagster/_core/execution/plan/utils.py", line 57, in op_execution_error_boundary
    yield
  File "/usr/local/lib/python3.10/site-packages/dagster/_utils/__init__.py", line 392, in iterate_with_context
    next_output = next(iterator)
  File "/usr/local/lib/python3.10/site-packages/dagster/_core/execution/plan/compute_generator.py", line 137, in _coerce_op_compute_fn_to_iterator
    result = invoke_compute_fn(
  File "/usr/local/lib/python3.10/site-packages/dagster/_core/execution/plan/compute_generator.py", line 117, in invoke_compute_fn
    return fn(context, **args_to_pass) if context_arg_provided else fn(**args_to_pass)
  File "/app/dagster_project/assets/trigger_api.py", line 17, in trigger_transform_api
    response = httpx.post(API_URL, json=payload, timeout=60)
  File "/usr/local/lib/python3.10/site-packages/httpx/_api.py", line 304, in post
    return request(
  File "/usr/local/lib/python3.10/site-packages/httpx/_api.py", line 109, in request
    return client.request(
  File "/usr/local/lib/python3.10/site-packages/httpx/_client.py", line 825, in request
    return self.send(request, auth=auth, follow_redirects=follow_redirects)
  File "/usr/local/lib/python3.10/site-packages/httpx/_client.py", line 914, in send
    response = self._send_handling_auth(
  File "/usr/local/lib/python3.10/site-packages/httpx/_client.py", line 942, in _send_handling_auth
    response = self._send_handling_redirects(
  File "/usr/local/lib/python3.10/site-packages/httpx/_client.py", line 979, in _send_handling_redirects
    response = self._send_single_request(request)
  File "/usr/local/lib/python3.10/site-packages/httpx/_client.py", line 1014, in _send_single_request
    response = transport.handle_request(request)
  File "/usr/local/lib/python3.10/site-packages/httpx/_transports/default.py", line 249, in handle_request
    with map_httpcore_exceptions():
  File "/usr/local/lib/python3.10/contextlib.py", line 153, in __exit__
    self.gen.throw(typ, value, traceback)
  File "/usr/local/lib/python3.10/site-packages/httpx/_transports/default.py", line 118, in map_httpcore_exceptions
    raise mapped_exc(message) from exc

The above exception was caused by the following exception:
httpcore.ConnectError: [Errno -3] Temporary failure in name resolution

Stack Trace:
  File "/usr/local/lib/python3.10/site-packages/httpx/_transports/default.py", line 101, in map_httpcore_exceptions
    yield
  File "/usr/local/lib/python3.10/site-packages/httpx/_transports/default.py", line 250, in handle_request
    resp = self._pool.handle_request(req)
  File "/usr/local/lib/python3.10/site-packages/httpcore/_sync/connection_pool.py", line 256, in handle_request
    raise exc from None
  File "/usr/local/lib/python3.10/site-packages/httpcore/_sync/connection_pool.py", line 236, in handle_request
    response = connection.handle_request(
  File "/usr/local/lib/python3.10/site-packages/httpcore/_sync/connection.py", line 101, in handle_request
    raise exc
  File "/usr/local/lib/python3.10/site-packages/httpcore/_sync/connection.py", line 78, in handle_request
    stream = self._connect(request)
  File "/usr/local/lib/python3.10/site-packages/httpcore/_sync/connection.py", line 124, in _connect
    stream = self._network_backend.connect_tcp(**kwargs)
  File "/usr/local/lib/python3.10/site-packages/httpcore/_backends/sync.py", line 207, in connect_tcp
    with map_exceptions(exc_map):
  File "/usr/local/lib/python3.10/contextlib.py", line 153, in __exit__
    self.gen.throw(typ, value, traceback)
  File "/usr/local/lib/python3.10/site-packages/httpcore/_exceptions.py", line 14, in map_exceptions
    raise to_exc(exc) from exc

