2025-08-03 16:21:22 +0000 - dagster - DEBUG - __ASSET_JOB - 057b2c6d-3835-4c8a-8aa6-ab1d7a81cb32 - 1428 - LOGS_CAPTURED - Started capturing logs in process (pid: 1428).
2025-08-03 16:21:22 +0000 - dagster - DEBUG - __ASSET_JOB - 057b2c6d-3835-4c8a-8aa6-ab1d7a81cb32 - 1428 - trigger_transform_api - STEP_START - Started execution of step "trigger_transform_api".
2025-08-03 16:21:22 +0000 - dagster - ERROR - __ASSET_JOB - 057b2c6d-3835-4c8a-8aa6-ab1d7a81cb32 - 1428 - trigger_transform_api - STEP_FAILURE - Execution of step "trigger_transform_api" failed.

dagster._core.errors.DagsterExecutionStepExecutionError: Error occurred while executing op "trigger_transform_api"::

requests.exceptions.ConnectionError: HTTPConnectionPool(host='fastapi-transformer', port=8000): Max retries exceeded with url: /transform (Caused by NameResolutionError("<urllib3.connection.HTTPConnection object at 0x7e40d1b54400>: Failed to resolve 'fastapi-transformer' ([Errno -3] Temporary failure in name resolution)"))

Stack Trace:
  File "/usr/local/lib/python3.10/site-packages/dagster/_core/execution/plan/utils.py", line 57, in op_execution_error_boundary
    yield
  File "/usr/local/lib/python3.10/site-packages/dagster/_utils/__init__.py", line 392, in iterate_with_context
    next_output = next(iterator)
  File "/usr/local/lib/python3.10/site-packages/dagster/_core/execution/plan/compute_generator.py", line 137, in _coerce_op_compute_fn_to_iterator
    result = invoke_compute_fn(
  File "/usr/local/lib/python3.10/site-packages/dagster/_core/execution/plan/compute_generator.py", line 117, in invoke_compute_fn
    return fn(context, **args_to_pass) if context_arg_provided else fn(**args_to_pass)
  File "/app/dagster_project/assets/trigger_api.py", line 23, in trigger_transform_api
    response = requests.post(
  File "/usr/local/lib/python3.10/site-packages/requests/api.py", line 115, in post
    return request("post", url, data=data, json=json, **kwargs)
  File "/usr/local/lib/python3.10/site-packages/requests/api.py", line 59, in request
    return session.request(method=method, url=url, **kwargs)
  File "/usr/local/lib/python3.10/site-packages/requests/sessions.py", line 589, in request
    resp = self.send(prep, **send_kwargs)
  File "/usr/local/lib/python3.10/site-packages/requests/sessions.py", line 703, in send
    r = adapter.send(request, **kwargs)
  File "/usr/local/lib/python3.10/site-packages/requests/adapters.py", line 700, in send
    raise ConnectionError(e, request=request)

The above exception occurred during handling of the following exception:
urllib3.exceptions.MaxRetryError: HTTPConnectionPool(host='fastapi-transformer', port=8000): Max retries exceeded with url: /transform (Caused by NameResolutionError("<urllib3.connection.HTTPConnection object at 0x7e40d1b54400>: Failed to resolve 'fastapi-transformer' ([Errno -3] Temporary failure in name resolution)"))

Stack Trace:
  File "/usr/local/lib/python3.10/site-packages/requests/adapters.py", line 667, in send
    resp = conn.urlopen(
  File "/usr/local/lib/python3.10/site-packages/urllib3/connectionpool.py", line 841, in urlopen
    retries = retries.increment(
  File "/usr/local/lib/python3.10/site-packages/urllib3/util/retry.py", line 519, in increment
    raise MaxRetryError(_pool, url, reason) from reason  # type: ignore[arg-type]

The above exception was caused by the following exception:
urllib3.exceptions.NameResolutionError: <urllib3.connection.HTTPConnection object at 0x7e40d1b54400>: Failed to resolve 'fastapi-transformer' ([Errno -3] Temporary failure in name resolution)

Stack Trace:
  File "/usr/local/lib/python3.10/site-packages/urllib3/connectionpool.py", line 787, in urlopen
    response = self._make_request(
  File "/usr/local/lib/python3.10/site-packages/urllib3/connectionpool.py", line 493, in _make_request
    conn.request(
  File "/usr/local/lib/python3.10/site-packages/urllib3/connection.py", line 494, in request
    self.endheaders()
  File "/usr/local/lib/python3.10/http/client.py", line 1278, in endheaders
    self._send_output(message_body, encode_chunked=encode_chunked)
  File "/usr/local/lib/python3.10/http/client.py", line 1038, in _send_output
    self.send(msg)
  File "/usr/local/lib/python3.10/http/client.py", line 976, in send
    self.connect()
  File "/usr/local/lib/python3.10/site-packages/urllib3/connection.py", line 325, in connect
    self.sock = self._new_conn()
  File "/usr/local/lib/python3.10/site-packages/urllib3/connection.py", line 205, in _new_conn
    raise NameResolutionError(self.host, self, e) from e

The above exception was caused by the following exception:
socket.gaierror: [Errno -3] Temporary failure in name resolution

Stack Trace:
  File "/usr/local/lib/python3.10/site-packages/urllib3/connection.py", line 198, in _new_conn
    sock = connection.create_connection(
  File "/usr/local/lib/python3.10/site-packages/urllib3/util/connection.py", line 60, in create_connection
    for res in socket.getaddrinfo(host, port, family, socket.SOCK_STREAM):
  File "/usr/local/lib/python3.10/socket.py", line 967, in getaddrinfo
    for res in _socket.getaddrinfo(host, port, family, type, proto, flags):

